<?xml version="1.0" encoding="utf-8"?>

<robot name="mini_robot_description" xmlns:xacro="http://www.ros.org/wiki/xacro">

<!-- #############  INCLUDE GAZEBO PARAMS ############# -->
<xacro:include filename="$(find mini_robot_description)/gazebo/mini_robot_description_materials.gazebo" />
<xacro:include filename="$(find mini_robot_description)/gazebo/mini_robot_description_physics.gazebo" />
<xacro:include filename="$(find mini_robot_description)/gazebo/mini_robot_description_plugins.gazebo" />

<!-- ############# Material ############# -->
<xacro:include filename="$(find mini_robot_description)/urdf/materials.urdf" />



<!-- ############# LINKS ############# -->

<!-- <link name="dummy"></link> -->

  <link name="base_link">
    <inertial>
      <origin xyz="0 0 0" rpy="0 0 0" />
      <mass value="5.62609" />
      <inertia ixx="0.0011527" ixy="-6.6808E-08" ixz="3.2285E-07" iyy="0.0023193" iyz="-1.2268E-06" izz="0.0012482" />
    </inertial>
    <visual>
      <origin xyz="0 0 0" rpy="0 0 0" />
      <geometry>
        <mesh  filename="package://mini_robot_description/meshes/base_link.STL" />
      </geometry>
      <material name="white"/>
    </visual>
    <collision>
      <origin  xyz="0 0 0" rpy="0 0 0" />
      <geometry>
        <mesh filename="package://mini_robot_description/meshes/base_link.STL" />
      </geometry>
    </collision>
  </link>

  <link name="right_wheel_link">
    <inertial>
      <origin xyz="0 0 0" rpy="0 0 0" />
      <mass value="1.26404" />
      <inertia  ixx="0.0011527"  ixy="-6.6808E-08"  ixz="3.2285E-07"  iyy="0.0023193"  iyz="-1.2268E-06"  izz="0.0012482" />
    </inertial>
    <visual>
      <origin xyz="0 0 0" rpy="0 0 0" />
      <geometry>
        <mesh filename="package://mini_robot_description/meshes/right_wheel_link.STL" />
      </geometry>
      <material name="black"/>
    </visual>
    <collision>
      <origin xyz="0 0 0" rpy="0 0 0" />
      <geometry>
        <mesh filename="package://mini_robot_description/meshes/right_wheel_link.STL" />
      </geometry>
    </collision>
  </link>
  
  <link name="left_wheel_link">
    <inertial>
      <origin xyz="0 0 0" rpy="0 0 0" />
      <mass value="1.26404" />
      <inertia  ixx="0.0011527"  ixy="-6.6808E-08"  ixz="3.2285E-07"  iyy="0.0023193"  iyz="-1.2268E-06"  izz="0.0012482" />
    </inertial>
    <visual>
      <origin xyz="0 0 0" rpy="0 0 0" />
      <geometry>
        <mesh filename="package://mini_robot_description/meshes/right_wheel_link.STL" />
      </geometry>
      <material name="black"/>
    </visual>
    <collision>
      <origin xyz="0 0 0" rpy="0 0 0" />
      <geometry>
        <mesh filename="package://mini_robot_description/meshes/right_wheel_link.STL" />
      </geometry>
    </collision>
  </link>


  <link name="support_lidar">
    <inertial>
      <origin xyz="0 0 0" rpy="0 0 0" />
      <mass value="0.26" />
      <inertia ixx="3.3e-05" ixy="0.0" ixz="0.0" iyy="3.3e-05" iyz="0.0" izz="6e-05"/>
    </inertial>
    <visual>
      <origin rpy="0 0 0" xyz="0 0 0"/>
      <geometry>
        <cylinder radius="0.04"   length="0.02"/>
      </geometry>
      <material name="blue"/>
    </visual>
    <collision>
      <origin rpy="0 0 0" xyz="0 0 0"/>
      <geometry>
        <cylinder radius="0.04"   length="0.02"/>
      </geometry>
    </collision>
  </link>

  <link name="lidar_link">
    <inertial>
      <origin rpy="0 0 0" xyz="-2.3483549826952554e-09 -3.4770506128023716e-07 0.009561590682608923"/>
      <mass value="0.886181648250366"/>
      <inertia ixx="3.3e-05" ixy="0.0" ixz="0.0" iyy="3.3e-05" iyz="0.0" izz="6e-05"/>
    </inertial>
    <visual>
      <origin rpy="0 0 0" xyz="-0.1575 0.0 -0.3"/>
      <geometry>
        <mesh filename="package://mini_robot_description/meshes/lidar.stl" scale="0.001 0.001 0.001"/>
      </geometry>
      <material name="blue"/>
    </visual>
    <collision>
      <origin rpy="0 0 0" xyz="-0.1575 0.0 -0.3"/>
      <geometry>
        <mesh filename="package://mini_robot_description/meshes/lidar.stl" scale="0.001 0.001 0.001"/>
      </geometry>
    </collision>
  </link>


<!-- ############# JOINTS ############# -->

  <!-- <joint name="dummy_joint" type="fixed">
     <parent link="dummy"/>
     <child link="base_link"/>
   </joint> -->

  <joint name="right_joint" type="continuous">
    <origin xyz="0 -0.06726 0.01625" rpy="1.5708 0.085809 0" />
    <parent link="base_link" />
    <child link="right_wheel_link" />
    <dynamics damping="0.07" friction="1.0"/>
    <limit effort="5" velocity="1.0"/>
    <axis xyz="0 0 -1" />
  </joint>

  <joint name="left_joint" type="continuous">
    <origin xyz="0 0.06726 0.01625" rpy="1.5708 -0.042963 3.1416" />
    <parent link="base_link" />
    <child link="left_wheel_link" />
    <dynamics damping="0.07" friction="1.0"/>
    <limit effort="5" velocity="1.0"/>
    <axis  xyz="0 0 1" />
  </joint>

  <joint name="support_lidar_joint" type="fixed">
    <origin xyz="0 0.0 0.14" rpy="0.0 0.0 0.0" />
    <parent link="base_link" />
    <child link="support_lidar" />
  </joint>

  <joint name="lidar_joint" type="fixed">
    <origin xyz="0 0.0 0.15" rpy="0.0 0.0 0.0" />
    <parent link="base_link" />
    <child link="lidar_link" />
  </joint>

</robot>
