<?xml version="1.0" encoding="utf-8"?>
<!-- This URDF was automatically created by SolidWorks to URDF Exporter! Originally created by Stephen Brawner (brawner@gmail.com) 
     Commit Version: 1.6.0-1-g15f4949  Build Version: 1.6.7594.29634
     For more information, please see http://wiki.ros.org/sw_urdf_exporter -->
<robot
  name="mini_robot_description">
  <link
    name="base_link">
    <inertial>
      <origin
        xyz="-0.0010741 -0.00014572 0.058673"
        rpy="0 0 0" />
      <mass
        value="0.62609" />
      <inertia
        ixx="0.0012482"
        ixy="3.2285E-07"
        ixz="1.2268E-06"
        iyy="0.0011527"
        iyz="6.6808E-08"
        izz="0.0023193" />
    </inertial>
    <visual>
      <origin
        xyz="0 0 0"
        rpy="0 0 0" />
      <geometry>
        <mesh
          filename="package://mini_robot_description/meshes/base_link.STL" />
      </geometry>
      <material
        name="">
        <color
          rgba="0.75294 0.75294 0.75294 1" />
      </material>
    </visual>
    <collision>
      <origin
        xyz="0 0 0"
        rpy="0 0 0" />
      <geometry>
        <mesh
          filename="package://mini_robot_description/meshes/base_link.STL" />
      </geometry>
    </collision>
  </link>
  <link
    name="rightwheel_link">
    <inertial>
      <origin
        xyz="0 -0.013607 1.3184E-16"
        rpy="0 0 0" />
      <mass
        value="0.026404" />
      <inertia
        ixx="1.1851E-05"
        ixy="1.8002E-22"
        ixz="-3.0644E-21"
        iyy="2.0597E-05"
        iyz="-9.3668E-20"
        izz="1.1851E-05" />
    </inertial>
    <visual>
      <origin
        xyz="0 0 0"
        rpy="0 0 0" />
      <geometry>
        <mesh
          filename="package://mini_robot_description/meshes/rightwheel_link.STL" />
      </geometry>
      <material
        name="">
        <color
          rgba="0.75294 0.75294 0.75294 1" />
      </material>
    </visual>
    <collision>
      <origin
        xyz="0 0 0"
        rpy="0 0 0" />
      <geometry>
        <mesh
          filename="package://mini_robot_description/meshes/rightwheel_link.STL" />
      </geometry>
    </collision>
  </link>
  <joint
    name="rightwheel_joint"
    type="continuous">
    <origin
      xyz="0 -0.06726 0.01625"
      rpy="0 0 0" />
    <parent
      link="base_link" />
    <child
      link="rightwheel_link" />
    <axis
      xyz="0 -1 0" />
  </joint>
  <link
    name="leftwheel_link">
    <inertial>
      <origin
        xyz="0 0.013607 -1.3878E-17"
        rpy="0 0 0" />
      <mass
        value="0.026404" />
      <inertia
        ixx="1.1851E-05"
        ixy="-1.4255E-21"
        ixz="2.6989E-21"
        iyy="2.0597E-05"
        iyz="1.2507E-21"
        izz="1.1851E-05" />
    </inertial>
    <visual>
      <origin
        xyz="0 0 0"
        rpy="0 0 0" />
      <geometry>
        <mesh
          filename="package://mini_robot_description/meshes/leftwheel_link.STL" />
      </geometry>
      <material
        name="">
        <color
          rgba="0.75294 0.75294 0.75294 1" />
      </material>
    </visual>
    <collision>
      <origin
        xyz="0 0 0"
        rpy="0 0 0" />
      <geometry>
        <mesh
          filename="package://mini_robot_description/meshes/leftwheel_link.STL" />
      </geometry>
    </collision>
  </link>
  <joint
    name="leftwheel_joint"
    type="continuous">
    <origin
      xyz="0 0.06726 0.01625"
      rpy="0 0 0" />
    <parent
      link="base_link" />
    <child
      link="leftwheel_link" />
    <axis
      xyz="0 1 0" />
  </joint>
</robot>