<?xml version="1.0" encoding="utf-8"?>

<robot name="robot_resto_urdf">

  <gazebo>
    <plugin name="gazebo_ros_control" filename="libgazebo_ros_control.so">
      <robotNamespace>/</robotNamespace>
      <legacyModeNS> true </legacyModeNS>
    </plugin>
  </gazebo>

  <link name="base_link">
    <inertial>
      <origin xyz="0 0 0" rpy="0 0 0" />
      <mass value="0.62609" />
      <inertia
        ixx="0.0011527"
        ixy="-6.6808E-08"
        ixz="3.2285E-07"
        iyy="0.0023193"
        iyz="-1.2268E-06"
        izz="0.0012482" />
    </inertial>
    <visual>
      <origin xyz="0 0 0" rpy="0 0 0" />
      <geometry>
        <mesh  filename="package://robot_resto_urdf/meshes/base_link.STL" />
      </geometry>
      <material
        name="">
        <color rgba="0.75294 0.75294 0.75294 1" />
      </material>
    </visual>
    <collision>
      <origin  xyz="0 0 0" rpy="0 0 0" />
      <geometry>
        <mesh filename="package://robot_resto_urdf/meshes/base_link.STL" />
      </geometry>
    </collision>
  </link>

  <link name="right_wheel_link">
    <inertial>
      <origin xyz="0 0 0" rpy="0 0 0" />
      <mass value="0.026404" />
      <inertia
        ixx="0"
        ixy="0"
        ixz="0"
        iyy="0"
        iyz="0"
        izz="0" />
    </inertial>
    <visual>
      <origin xyz="0 0 0" rpy="0 0 0" />
      <geometry>
        <mesh filename="package://robot_resto_urdf/meshes/right_wheel_link.STL" />
      </geometry>
      <material
        name="">
        <color rgba="0.75294 0.75294 0.75294 1" />
      </material>
    </visual>
    <collision>
      <origin xyz="0 0 0" rpy="0 0 0" />
      <geometry>
        <mesh filename="package://robot_resto_urdf/meshes/right_wheel_link.STL" />
      </geometry>
    </collision>
  </link>
  
  <joint name="right_joint" type="continuous">
    <origin xyz="0 -0.06726 0.01625" rpy="1.5708 0.085809 0" />
    <parent link="base_link" />
    <child link="right_wheel_link" />
    <dynamics damping="0.07" friction="1.0"/>
    <limit effort="5" velocity="1.0"/>
    <axis xyz="0 0 1" />
  </joint>

  <link name="left_wheel_link">
    <inertial>
      <origin xyz="0 0 0" rpy="0 0 0" />
      <mass value="0.026404" />
      <inertia
        ixx="0"
        ixy="0"
        ixz="0"
        iyy="0"
        iyz="0"
        izz="0" />
    </inertial>
    <visual>
      <origin xyz="0 0 0" rpy="0 0 0" />
      <geometry>
        <mesh filename="package://robot_resto_urdf/meshes/right_wheel_link.STL" />
      </geometry>
      <material
        name="">
        <color rgba="1 1 1 1" />
      </material>
    </visual>
    <collision>
      <origin xyz="0 0 0" rpy="0 0 0" />
      <geometry>
        <mesh filename="package://robot_resto_urdf/meshes/right_wheel_link.STL" />
      </geometry>
    </collision>
  </link>

  <joint name="left_joint" type="continuous">
    <origin xyz="0 0.06726 0.01625" rpy="1.5708 -0.042963 3.1416" />
    <parent link="base_link" />
    <child link="left_wheel_link" />
    <dynamics damping="0.07" friction="1.0"/>
    <limit effort="5" velocity="1.0"/>
    <axis  xyz="0 0 1" />
  </joint>



  <!-- Gazebo-specific link properties  -->
  <gazebo reference="base_link">
    <material>Gazebo/Orange</material>
    <turnGravityOff>false</turnGravityOff>
    <mu1 value="200.0"/>
    <mu2 value="100.0"/>
    <kp value="10000000.0" />
    <kd value="1.0" />
  </gazebo>

  
  <gazebo reference="right_wheel_link">
    <material>Gazebo/Black</material>
    <turnGravityOff>false</turnGravityOff>
    <mu1 value="200.0"/>
    <mu2 value="100.0"/>
    <kp value="10000000.0" />
    <kd value="1.0" />
  </gazebo>

 
  <gazebo reference="left_wheel_link">
    <material>Gazebo/Black</material>
    <turnGravityOff>false</turnGravityOff>
    <mu1 value="200.0"/>
    <mu2 value="100.0"/>
    <kp value="10000000.0" />
    <kd value="1.0" />
  </gazebo>


 <transmission name="right_wheel_trans">
    <type>transmission_interface/SimpleTransmission</type>
    <actuator name="$right_motor">
      <mechanicalReduction>1</mechanicalReduction>
    </actuator>
    <joint name="right_joint">
      <hardwareInterface>hardware_interface/VelocityJointInterface</hardwareInterface>
    </joint>
  </transmission>

  <transmission name="left_wheel_trans">
    <type>transmission_interface/SimpleTransmission</type>
    <actuator name="$left_motor">
      <mechanicalReduction>1</mechanicalReduction>
    </actuator>
    <joint name="left_joint">
      <hardwareInterface>hardware_interface/VelocityJointInterface</hardwareInterface>
    </joint>
  </transmission>


</robot>
